File: Test Data/Steel_1045_Normalized_2_Formatted.csv
Time (s),Extension (mm),Load (kN),Strain (mm/mm),Original Length (mm),Original Diameter (mm),Final Length (mm),Final Diameter (mm)
0,0,0.2547,0.00004889,25.4,7.08,30.2,5.5
0.5,0.03,0.8217,0.0001087,,,,
1,0.06,1.465,0.0002285,,,,
1.5,0.1,2.175,0.000313,,,,
2,0.13,2.815,0.0003865,,,,
2.5,0.16,3.343,0.0004493,,,,
3,0.2,3.799,0.000509,,,,
3.5,0.23,4.215,0.0005651,,,,
4,0.26,4.609,0.0005907,,,,
4.5,0.29,4.99,0.0006291,,,,
5,0.33,5.35,0.0006727,,,,
5.5,0.36,5.69,0.0007183,,,,
6,0.4,6.019,0.0007568,,,,
6.5,0.43,6.327,0.0007976,,,,
7,0.46,6.613,0.0008437,,,,
7.5,0.5,6.898,0.0008747,,,,
8,0.53,7.166,0.000902,,,,
8.5,0.56,7.428,0.0009262,,,,
9,0.6,7.685,0.0009585,,,,
9.5,0.63,7.93,0.0009881,,,,
10,0.66,8.179,0.001026,,,,
10.5,0.7,8.426,0.001039,,,,
11,0.73,8.672,0.001074,,,,
11.5,0.76,8.921,0.001101,,,,
12,0.8,9.173,0.00113,,,,
12.5,0.83,9.419,0.00117,,,,
13,0.86,9.669,0.00119,,,,
13.5,0.9,9.914,0.001223,,,,
14,0.93,10.17,0.001262,,,,
14.5,0.96,10.43,0.00127,,,,
15,1,10.69,0.001309,,,,
15.5,1.03,10.94,0.001333,,,,
16,1.06,11.21,0.001377,,,,
16.5,1.1,11.47,0.001409,,,,
17,1.13,11.74,0.001436,,,,
17.5,1.16,12.01,0.001474,,,,
18,1.19,12.28,0.001511,,,,
18.5,1.23,12.55,0.001537,,,,
19,1.26,12.83,0.001584,,,,
19.5,1.3,13.1,0.00161,,,,
20,1.33,13.39,0.001644,,,,
20.5,1.36,13.67,0.001683,,,,
21,1.4,13.95,0.00172,,,,
21.5,1.43,14.24,0.001755,,,,
22,1.46,14.53,0.001784,,,,
22.5,1.5,14.82,0.001836,,,,
23,1.53,15.12,0.001863,,,,
23.5,1.56,15.41,0.001908,,,,
24,1.6,15.7,0.001957,,,,
24.5,1.63,16,0.001985,,,,
25,1.66,16.3,0.002023,,,,
25.5,1.7,16.61,0.002073,,,,
26,1.73,16.91,0.002108,,,,
26.5,1.76,17.21,0.002175,,,,
27,1.8,17.45,0.002497,,,,
27.5,1.83,17.43,0.003705,,,,
28,1.86,17.6,0.004454,,,,
28.5,1.9,17.7,0.005317,,,,
29,1.93,17.75,0.006264,,,,
29.5,1.96,17.76,0.007159,,,,
30,2,17.8,0.007882,,,,
30.5,2.03,17.82,0.008439,,,,
31,2.06,17.88,0.008818,,,,
31.5,2.1,17.89,0.009021,,,,
32,2.13,17.94,0.009166,,,,
32.5,2.16,18.07,0.009347,,,,
33,2.2,18.25,0.009687,,,,
33.5,2.23,18.43,0.01009,,,,
34,2.26,18.59,0.01049,,,,
34.5,2.3,18.74,0.01087,,,,
35,2.33,18.89,0.01127,,,,
35.5,2.36,19.04,0.01167,,,,
36,2.4,19.2,0.01206,,,,
36.5,2.43,19.34,0.01246,,,,
37,2.46,19.49,0.01285,,,,
37.5,2.5,19.64,0.01326,,,,
38,2.53,19.78,0.01364,,,,
38.5,2.56,19.93,0.01404,,,,
39,2.6,20.07,0.01444,,,,
39.5,2.63,20.21,0.01486,,,,
40,2.66,20.35,0.01526,,,,
40.5,2.7,20.49,0.01567,,,,
41,2.73,20.63,0.01608,,,,
41.5,2.76,20.77,0.01649,,,,
42,2.8,20.91,0.0169,,,,
42.5,2.83,21.04,0.01733,,,,
43,2.86,21.18,0.01776,,,,
43.5,2.9,21.32,0.01817,,,,
44,2.93,21.45,0.01859,,,,
44.5,2.96,21.59,0.01903,,,,
45,3,21.72,0.01947,,,,
45.5,3.03,21.85,0.01989,,,,
46,3.06,21.98,0.02033,,,,
46.5,3.09,22.1,0.02076,,,,
47,3.13,22.24,0.0212,,,,
47.5,3.16,22.36,0.02166,,,,
48,3.2,22.49,0.0221,,,,
48.5,3.23,22.61,0.02255,,,,
49,3.26,22.74,0.02298,,,,
49.5,3.29,22.86,0.02344,,,,
50,3.33,22.98,0.02389,,,,
50.5,3.36,23.1,0.02434,,,,
51,3.4,23.22,0.0248,,,,
51.5,3.43,23.34,0.02526,,,,
52,3.46,23.46,0.02573,,,,
52.5,3.5,23.57,0.02619,,,,
53,3.53,23.69,0.02667,,,,
53.5,3.56,23.8,0.02715,,,,
54,3.6,23.92,0.02763,,,,
54.5,3.63,24.03,0.0281,,,,
55,3.66,24.14,0.0286,,,,
55.5,3.7,24.25,0.02908,,,,
56,3.73,24.36,0.02957,,,,
56.5,3.76,24.47,0.03006,,,,
57,3.8,24.57,0.03057,,,,
57.5,3.83,24.67,0.03106,,,,
58,3.86,24.78,0.03156,,,,
58.5,3.9,24.88,0.03206,,,,
59,3.93,24.98,0.03258,,,,
59.5,3.96,25.08,0.0331,,,,
60,4,25.18,0.03361,,,,
60.5,4.03,25.28,0.03413,,,,
61,4.06,25.37,0.03464,,,,
61.5,4.1,25.47,0.03517,,,,
62,4.13,25.56,0.03569,,,,
62.5,4.16,25.65,0.03621,,,,
63,4.2,25.74,0.03675,,,,
63.5,4.23,25.83,0.03728,,,,
64,4.26,25.92,0.03782,,,,
64.5,4.3,26.01,0.03836,,,,
65,4.33,26.09,0.03892,,,,
65.5,4.36,26.18,0.03947,,,,
66,4.4,26.26,0.04002,,,,
66.5,4.43,26.34,0.04058,,,,
67,4.46,26.42,0.04114,,,,
67.5,4.5,26.5,0.04171,,,,
68,4.53,26.58,0.04228,,,,
68.5,4.56,26.66,0.04285,,,,
69,4.6,26.73,0.04342,,,,
69.5,4.63,26.81,0.04401,,,,
70,4.66,26.88,0.04459,,,,
70.5,4.7,26.95,0.04517,,,,
71,4.73,27.02,0.04575,,,,
71.5,4.76,27.09,0.04636,,,,
72,4.8,27.16,0.04696,,,,
72.5,4.83,27.23,0.04757,,,,
73,4.86,27.29,0.04816,,,,
73.5,4.9,27.36,0.04877,,,,
74,4.93,27.42,0.04938,,,,
74.5,4.96,27.48,0.05,,,,
75,5,27.54,0.05061,,,,
75.5,5.03,27.6,0.05123,,,,
76,5.06,27.67,0.05186,,,,
76.5,5.1,27.72,0.05248,,,,
77,5.13,27.78,0.05313,,,,
77.5,5.16,27.83,0.05377,,,,
78,5.19,27.88,0.05441,,,,
78.5,5.23,27.94,0.05506,,,,
79,5.26,27.99,0.0557,,,,
79.5,5.3,28.04,0.05636,,,,
80,5.33,28.09,0.05701,,,,
80.5,5.36,28.14,0.05767,,,,
81,5.4,28.19,0.05834,,,,
81.5,5.43,28.24,0.05901,,,,
82,5.46,28.28,0.05968,,,,
82.5,5.5,28.33,0.06036,,,,
83,5.53,28.37,0.06103,,,,
83.5,5.56,28.41,0.06172,,,,
84,5.6,28.46,0.0624,,,,
84.5,5.63,28.5,0.06309,,,,
85,5.66,28.54,0.06377,,,,
85.5,5.7,28.58,0.06448,,,,
86,5.73,28.61,0.06517,,,,
86.5,5.76,28.65,0.06589,,,,
87,5.8,28.69,0.06659,,,,
87.5,5.83,28.72,0.0673,,,,
88,5.86,28.76,0.06802,,,,
88.5,5.9,28.79,0.06874,,,,
89,5.93,28.82,0.06947,,,,
89.5,5.96,28.86,0.07019,,,,
90,6,28.89,0.07093,,,,
90.5,6.03,28.92,0.07167,,,,
91,6.06,28.95,0.0724,,,,
91.5,6.1,28.98,0.07314,,,,
92,6.13,29.01,0.07389,,,,
92.5,6.16,29.03,0.07465,,,,
93,6.2,29.06,0.0754,,,,
93.5,6.23,29.09,0.07617,,,,
94,6.26,29.11,0.07693,,,,
94.5,6.3,29.14,0.07769,,,,
95,6.33,29.16,0.07847,,,,
95.5,6.36,29.18,0.07925,,,,
96,6.4,29.21,0.08002,,,,
96.5,6.43,29.23,0.0808,,,,
97,6.46,29.25,0.0816,,,,
97.5,6.5,29.27,0.08239,,,,
98,6.53,29.29,0.08319,,,,
98.5,6.56,29.31,0.08399,,,,
99,6.6,29.33,0.08479,,,,
99.5,6.63,29.35,0.0856,,,,
100,6.66,29.37,0.08642,,,,
100.5,6.7,29.38,0.08724,,,,
101,6.73,29.4,0.08806,,,,
101.5,6.76,29.42,0.08889,,,,
102,6.8,29.43,0.08972,,,,
102.5,6.83,29.44,0.09056,,,,
103,6.86,29.46,0.09139,,,,
103.5,6.89,29.47,0.09224,,,,
104,6.93,29.49,0.0931,,,,
104.5,6.96,29.5,0.09396,,,,
105,7,29.51,0.09482,,,,
105.5,7.03,29.52,0.09569,,,,
106,7.06,29.53,0.09656,,,,
106.5,7.1,29.55,0.09743,,,,
107,7.13,29.55,0.09831,,,,
107.5,7.16,29.56,0.0992,,,,
108,7.2,29.57,0.1001,,,,
108.5,7.23,29.58,0.101,,,,
109,7.26,29.59,0.1019,,,,
109.5,7.3,29.6,0.1028,,,,
110,7.33,29.61,0.1037,,,,
110.5,7.36,29.61,0.1046,,,,
111,7.4,29.62,0.1055,,,,
111.5,7.43,29.62,0.1064,,,,
112,7.46,29.63,0.1074,,,,
112.5,7.5,29.64,0.1083,,,,
113,7.53,29.64,0.1093,,,,
113.5,7.56,29.64,0.1102,,,,
114,7.6,29.65,0.1112,,,,
114.5,7.63,29.65,0.1122,,,,
115,7.66,29.66,0.1131,,,,
115.5,7.69,29.66,0.1141,,,,
116,7.73,29.66,0.1151,,,,
116.5,7.76,29.66,0.1161,,,,
117,7.8,29.66,0.1171,,,,
117.5,7.83,29.66,0.1181,,,,
118,7.86,29.66,0.1191,,,,
118.5,7.9,29.67,0.1202,,,,
119,7.93,29.66,0.1212,,,,
119.5,7.96,29.66,0.1222,,,,
120,8,29.66,0.1233,,,,
120.5,8.03,29.65,0.1244,,,,
121,8.06,29.65,0.1254,,,,
121.5,8.1,29.65,0.1265,,,,
122,8.13,29.65,0.1276,,,,
122.5,8.16,29.64,0.1287,,,,
123,8.2,29.63,0.1298,,,,
123.5,8.23,29.63,0.1309,,,,
124,8.26,29.63,0.132,,,,
124.5,8.3,29.62,0.1331,,,,
125,8.33,29.61,0.1343,,,,
125.5,8.36,29.6,0.1354,,,,
126,8.39,29.59,0.1366,,,,
126.5,8.43,29.58,0.1378,,,,
127,8.46,29.57,0.139,,,,
127.5,8.5,29.56,0.1401,,,,
128,8.53,29.54,0.1414,,,,
128.5,8.56,29.53,0.1426,,,,
129,8.6,29.51,0.1438,,,,
129.5,8.63,29.49,0.145,,,,
130,8.66,29.47,0.1463,,,,
130.5,8.7,29.46,0.1475,,,,
131,8.73,29.44,0.1488,,,,
131.5,8.76,29.41,0.1501,,,,
132,8.79,29.38,0.1513,,,,
132.5,8.83,29.36,0.1526,,,,
133,8.86,29.34,0.1539,,,,
133.5,8.9,29.3,0.1552,,,,
134,8.93,29.27,0.1565,,,,
134.5,8.96,29.24,0.1579,,,,
135,9,29.2,0.1592,,,,
135.5,9.03,29.17,0.1605,,,,
136,9.06,29.13,0.1618,,,,
136.5,9.1,29.09,0.1632,,,,
137,9.13,29.05,0.1645,,,,
137.5,9.16,29.01,0.1659,,,,
138,9.2,28.97,0.1672,,,,
138.5,9.23,28.92,0.1686,,,,
139,9.26,28.87,0.1699,,,,
139.5,9.29,28.82,0.1713,,,,
140,9.33,28.77,0.1726,,,,
140.5,9.36,28.71,0.174,,,,
141,9.4,28.66,0.1753,,,,
141.5,9.43,28.6,0.1767,,,,
142,9.46,28.55,0.1781,,,,
142.5,9.5,28.48,0.1795,,,,
143,9.53,28.42,0.1808,,,,
143.5,9.56,28.36,0.1821,,,,
144,9.6,28.3,0.1835,,,,
144.5,9.63,28.23,0.1849,,,,
145,9.66,28.16,0.1863,,,,
145.5,9.7,28.09,0.1877,,,,
146,9.73,28.02,0.1891,,,,
146.5,9.76,27.95,0.1904,,,,
147,9.8,27.87,0.1918,,,,
147.5,9.83,27.79,0.1932,,,,
148,9.86,27.72,0.1946,,,,
148.5,9.9,27.63,0.196,,,,
149,9.93,27.55,0.1974,,,,
149.5,9.96,27.47,0.1988,,,,
150,10,27.38,0.2001,,,,
150.5,10.03,27.29,0.2015,,,,
151,10.06,27.2,0.2029,,,,
151.5,10.09,27.11,0.2043,,,,
152,10.13,27.02,0.2058,,,,
152.5,10.16,26.92,0.2072,,,,
153,10.2,26.82,0.2086,,,,
153.5,10.23,26.72,0.21,,,,
154,10.26,26.62,0.2114,,,,
154.5,10.29,26.51,0.2128,,,,
155,10.33,26.4,0.2142,,,,
155.5,10.36,26.29,0.2156,,,,
156,10.4,26.18,0.217,,,,
156.5,10.43,26.06,0.2185,,,,
157,10.46,25.93,0.2199,,,,
157.5,10.49,25.81,0.2213,,,,
158,10.53,25.68,0.2228,,,,
158.5,10.56,25.55,0.2242,,,,
159,10.6,25.41,0.2256,,,,
159.5,10.63,25.26,0.2271,,,,
160,10.66,25.1,0.2286,,,,